[2024-10-12T04:28:48.649-0500] {local_task_job_runner.py:120} INFO - ::group::Pre task execution logs
[2024-10-12T04:28:49.313-0500] {taskinstance.py:2076} INFO - Dependencies all met for dep_context=non-requeueable deps ti=<TaskInstance: monitor_maintain_dag_v1_3.prediction_model manual__2024-10-12T09:24:17.715612+00:00 [queued]>
[2024-10-12T04:28:49.323-0500] {taskinstance.py:2076} INFO - Dependencies all met for dep_context=requeueable deps ti=<TaskInstance: monitor_maintain_dag_v1_3.prediction_model manual__2024-10-12T09:24:17.715612+00:00 [queued]>
[2024-10-12T04:28:49.324-0500] {taskinstance.py:2306} INFO - Starting attempt 2 of 2
[2024-10-12T04:28:49.630-0500] {taskinstance.py:2330} INFO - Executing <Task(_PythonVirtualenvDecoratedOperator): prediction_model> on 2024-10-12 09:24:17.715612+00:00
[2024-10-12T04:28:49.693-0500] {warnings.py:112} WARNING - /home/***/.local/lib/python3.12/site-packages/***/task/task_runner/standard_task_runner.py:62: DeprecationWarning: This process (pid=262) is multi-threaded, use of fork() may lead to deadlocks in the child.
  pid = os.fork()

[2024-10-12T04:28:49.695-0500] {standard_task_runner.py:64} INFO - Started process 263 to run task
[2024-10-12T04:28:49.695-0500] {standard_task_runner.py:90} INFO - Running: ['***', 'tasks', 'run', 'monitor_maintain_dag_v1_3', 'prediction_model', 'manual__2024-10-12T09:24:17.715612+00:00', '--job-id', '41', '--raw', '--subdir', 'DAGS_FOLDER/train/train_dag.py', '--cfg-path', '/tmp/tmp6p2b0_h3']
[2024-10-12T04:28:49.697-0500] {standard_task_runner.py:91} INFO - Job 41: Subtask prediction_model
[2024-10-12T04:28:49.884-0500] {task_command.py:426} INFO - Running <TaskInstance: monitor_maintain_dag_v1_3.prediction_model manual__2024-10-12T09:24:17.715612+00:00 [running]> on host 9f5514a2a604
[2024-10-12T04:28:50.396-0500] {taskinstance.py:2648} INFO - Exporting env vars: AIRFLOW_CTX_DAG_OWNER='***' AIRFLOW_CTX_DAG_ID='monitor_maintain_dag_v1_3' AIRFLOW_CTX_TASK_ID='prediction_model' AIRFLOW_CTX_EXECUTION_DATE='2024-10-12T09:24:17.715612+00:00' AIRFLOW_CTX_TRY_NUMBER='2' AIRFLOW_CTX_DAG_RUN_ID='manual__2024-10-12T09:24:17.715612+00:00'
[2024-10-12T04:28:50.397-0500] {taskinstance.py:430} INFO - ::endgroup::
[2024-10-12T04:28:50.399-0500] {process_utils.py:183} INFO - Executing cmd: /home/***/.local/bin/python -m virtualenv /tmp/venv6jtgfc_3 --python=python
[2024-10-12T04:28:50.401-0500] {process_utils.py:187} INFO - Output:
[2024-10-12T04:28:55.017-0500] {process_utils.py:191} INFO - created virtual environment CPython3.12.4.final.0-64 in 1245ms
[2024-10-12T04:28:55.018-0500] {process_utils.py:191} INFO -   creator CPython3Posix(dest=/tmp/venv6jtgfc_3, clear=False, no_vcs_ignore=False, global=False)
[2024-10-12T04:28:55.019-0500] {process_utils.py:191} INFO -   seeder FromAppData(download=False, pip=bundle, via=copy, app_data_dir=/home/***/.local/share/virtualenv)
[2024-10-12T04:28:55.020-0500] {process_utils.py:191} INFO -     added seed packages: pip==24.1
[2024-10-12T04:28:55.021-0500] {process_utils.py:191} INFO -   activators BashActivator,CShellActivator,FishActivator,NushellActivator,PowerShellActivator,PythonActivator
[2024-10-12T04:28:55.061-0500] {process_utils.py:183} INFO - Executing cmd: /tmp/venv6jtgfc_3/bin/pip install -r /tmp/venv6jtgfc_3/requirements.txt
[2024-10-12T04:28:55.062-0500] {process_utils.py:187} INFO - Output:
[2024-10-12T04:28:56.994-0500] {process_utils.py:191} INFO - Collecting joblib (from -r /tmp/venv6jtgfc_3/requirements.txt (line 1))
[2024-10-12T04:28:56.996-0500] {process_utils.py:191} INFO -   Using cached joblib-1.4.2-py3-none-any.whl.metadata (5.4 kB)
[2024-10-12T04:28:57.342-0500] {process_utils.py:191} INFO - Collecting numpy (from -r /tmp/venv6jtgfc_3/requirements.txt (line 2))
[2024-10-12T04:28:57.345-0500] {process_utils.py:191} INFO -   Using cached numpy-2.1.2-cp312-cp312-manylinux_2_17_x86_64.manylinux2014_x86_64.whl.metadata (60 kB)
[2024-10-12T04:28:57.658-0500] {process_utils.py:191} INFO - Collecting pandas (from -r /tmp/venv6jtgfc_3/requirements.txt (line 3))
[2024-10-12T04:28:57.660-0500] {process_utils.py:191} INFO -   Using cached pandas-2.2.3-cp312-cp312-manylinux_2_17_x86_64.manylinux2014_x86_64.whl.metadata (89 kB)
[2024-10-12T04:28:57.880-0500] {process_utils.py:191} INFO - Collecting scikit-learn (from -r /tmp/venv6jtgfc_3/requirements.txt (line 4))
[2024-10-12T04:28:57.881-0500] {process_utils.py:191} INFO -   Using cached scikit_learn-1.5.2-cp312-cp312-manylinux_2_17_x86_64.manylinux2014_x86_64.whl.metadata (13 kB)
[2024-10-12T04:28:57.986-0500] {process_utils.py:191} INFO - Collecting python-dateutil>=2.8.2 (from pandas->-r /tmp/venv6jtgfc_3/requirements.txt (line 3))
[2024-10-12T04:28:57.988-0500] {process_utils.py:191} INFO -   Using cached python_dateutil-2.9.0.post0-py2.py3-none-any.whl.metadata (8.4 kB)
[2024-10-12T04:28:58.091-0500] {process_utils.py:191} INFO - Collecting pytz>=2020.1 (from pandas->-r /tmp/venv6jtgfc_3/requirements.txt (line 3))
[2024-10-12T04:28:58.093-0500] {process_utils.py:191} INFO -   Using cached pytz-2024.2-py2.py3-none-any.whl.metadata (22 kB)
[2024-10-12T04:28:58.151-0500] {process_utils.py:191} INFO - Collecting tzdata>=2022.7 (from pandas->-r /tmp/venv6jtgfc_3/requirements.txt (line 3))
[2024-10-12T04:28:58.152-0500] {process_utils.py:191} INFO -   Using cached tzdata-2024.2-py2.py3-none-any.whl.metadata (1.4 kB)
[2024-10-12T04:28:58.344-0500] {process_utils.py:191} INFO - Collecting scipy>=1.6.0 (from scikit-learn->-r /tmp/venv6jtgfc_3/requirements.txt (line 4))
[2024-10-12T04:28:58.346-0500] {process_utils.py:191} INFO -   Using cached scipy-1.14.1-cp312-cp312-manylinux_2_17_x86_64.manylinux2014_x86_64.whl.metadata (60 kB)
[2024-10-12T04:28:58.430-0500] {process_utils.py:191} INFO - Collecting threadpoolctl>=3.1.0 (from scikit-learn->-r /tmp/venv6jtgfc_3/requirements.txt (line 4))
[2024-10-12T04:28:58.432-0500] {process_utils.py:191} INFO -   Using cached threadpoolctl-3.5.0-py3-none-any.whl.metadata (13 kB)
[2024-10-12T04:28:58.522-0500] {process_utils.py:191} INFO - Collecting six>=1.5 (from python-dateutil>=2.8.2->pandas->-r /tmp/venv6jtgfc_3/requirements.txt (line 3))
[2024-10-12T04:28:58.524-0500] {process_utils.py:191} INFO -   Using cached six-1.16.0-py2.py3-none-any.whl.metadata (1.8 kB)
[2024-10-12T04:28:58.545-0500] {process_utils.py:191} INFO - Using cached joblib-1.4.2-py3-none-any.whl (301 kB)
[2024-10-12T04:28:58.548-0500] {process_utils.py:191} INFO - Using cached numpy-2.1.2-cp312-cp312-manylinux_2_17_x86_64.manylinux2014_x86_64.whl (16.0 MB)
[2024-10-12T04:28:58.583-0500] {process_utils.py:191} INFO - Using cached pandas-2.2.3-cp312-cp312-manylinux_2_17_x86_64.manylinux2014_x86_64.whl (12.7 MB)
[2024-10-12T04:28:58.608-0500] {process_utils.py:191} INFO - Using cached scikit_learn-1.5.2-cp312-cp312-manylinux_2_17_x86_64.manylinux2014_x86_64.whl (12.9 MB)
[2024-10-12T04:28:58.649-0500] {process_utils.py:191} INFO - Using cached python_dateutil-2.9.0.post0-py2.py3-none-any.whl (229 kB)
[2024-10-12T04:28:58.650-0500] {process_utils.py:191} INFO - Using cached pytz-2024.2-py2.py3-none-any.whl (508 kB)
[2024-10-12T04:28:58.653-0500] {process_utils.py:191} INFO - Using cached scipy-1.14.1-cp312-cp312-manylinux_2_17_x86_64.manylinux2014_x86_64.whl (40.8 MB)
[2024-10-12T04:28:58.736-0500] {process_utils.py:191} INFO - Using cached threadpoolctl-3.5.0-py3-none-any.whl (18 kB)
[2024-10-12T04:28:58.737-0500] {process_utils.py:191} INFO - Using cached tzdata-2024.2-py2.py3-none-any.whl (346 kB)
[2024-10-12T04:28:58.740-0500] {process_utils.py:191} INFO - Using cached six-1.16.0-py2.py3-none-any.whl (11 kB)
[2024-10-12T04:28:59.081-0500] {process_utils.py:191} INFO - Installing collected packages: pytz, tzdata, threadpoolctl, six, numpy, joblib, scipy, python-dateutil, scikit-learn, pandas
[2024-10-12T04:29:27.681-0500] {process_utils.py:191} INFO - Successfully installed joblib-1.4.2 numpy-2.1.2 pandas-2.2.3 python-dateutil-2.9.0.post0 pytz-2024.2 scikit-learn-1.5.2 scipy-1.14.1 six-1.16.0 threadpoolctl-3.5.0 tzdata-2024.2
[2024-10-12T04:29:27.993-0500] {process_utils.py:191} INFO - 
[2024-10-12T04:29:27.994-0500] {process_utils.py:191} INFO - [notice] A new release of pip is available: 24.1 -> 24.2
[2024-10-12T04:29:27.995-0500] {process_utils.py:191} INFO - [notice] To update, run: python -m pip install --upgrade pip
[2024-10-12T04:29:28.233-0500] {process_utils.py:183} INFO - Executing cmd: /tmp/venv6jtgfc_3/bin/python /tmp/venv-call5z06zbh3/script.py /tmp/venv-call5z06zbh3/script.in /tmp/venv-call5z06zbh3/script.out /tmp/venv-call5z06zbh3/string_args.txt /tmp/venv-call5z06zbh3/termination.log
[2024-10-12T04:29:28.234-0500] {process_utils.py:187} INFO - Output:
[2024-10-12T04:29:29.347-0500] {process_utils.py:191} INFO - Traceback (most recent call last):
[2024-10-12T04:29:29.348-0500] {process_utils.py:191} INFO -   File "/tmp/venv-call5z06zbh3/script.py", line 63, in <module>
[2024-10-12T04:29:29.349-0500] {process_utils.py:191} INFO -     res = task_predictionnmodel(*arg_dict["args"], **arg_dict["kwargs"])
[2024-10-12T04:29:29.350-0500] {process_utils.py:191} INFO -           ^^^^^^^^^^^^^^^^^^^^^^^^^^^^^^^^^^^^^^^^^^^^^^^^^^^^^^^^^^^^^^
[2024-10-12T04:29:29.350-0500] {process_utils.py:191} INFO -   File "/tmp/venv-call5z06zbh3/script.py", line 28, in task_predictionnmodel
[2024-10-12T04:29:29.351-0500] {process_utils.py:191} INFO -     classifier = load("/opt/***/dags/data/model/best_lasso_model.joblib")
[2024-10-12T04:29:29.351-0500] {process_utils.py:191} INFO -                  ^^^^^^^^^^^^^^^^^^^^^^^^^^^^^^^^^^^^^^^^^^^^^^^^^^^^^^^^^^^^
[2024-10-12T04:29:29.352-0500] {process_utils.py:191} INFO -   File "/tmp/venv6jtgfc_3/lib/python3.12/site-packages/joblib/numpy_pickle.py", line 650, in load
[2024-10-12T04:29:29.353-0500] {process_utils.py:191} INFO -     with open(filename, 'rb') as f:
[2024-10-12T04:29:29.353-0500] {process_utils.py:191} INFO -          ^^^^^^^^^^^^^^^^^^^^
[2024-10-12T04:29:29.354-0500] {process_utils.py:191} INFO - FileNotFoundError: [Errno 2] No such file or directory: '/opt/***/dags/data/model/best_lasso_model.joblib'
[2024-10-12T04:29:29.769-0500] {taskinstance.py:441} INFO - ::group::Post task execution logs
[2024-10-12T04:29:29.779-0500] {taskinstance.py:2905} ERROR - Task failed with exception
Traceback (most recent call last):
  File "/home/airflow/.local/lib/python3.12/site-packages/airflow/models/taskinstance.py", line 465, in _execute_task
    result = _execute_callable(context=context, **execute_callable_kwargs)
             ^^^^^^^^^^^^^^^^^^^^^^^^^^^^^^^^^^^^^^^^^^^^^^^^^^^^^^^^^^^^^
  File "/home/airflow/.local/lib/python3.12/site-packages/airflow/models/taskinstance.py", line 432, in _execute_callable
    return execute_callable(context=context, **execute_callable_kwargs)
           ^^^^^^^^^^^^^^^^^^^^^^^^^^^^^^^^^^^^^^^^^^^^^^^^^^^^^^^^^^^^
  File "/home/airflow/.local/lib/python3.12/site-packages/airflow/models/baseoperator.py", line 401, in wrapper
    return func(self, *args, **kwargs)
           ^^^^^^^^^^^^^^^^^^^^^^^^^^^
  File "/home/airflow/.local/lib/python3.12/site-packages/airflow/decorators/base.py", line 265, in execute
    return_value = super().execute(context)
                   ^^^^^^^^^^^^^^^^^^^^^^^^
  File "/home/airflow/.local/lib/python3.12/site-packages/airflow/models/baseoperator.py", line 401, in wrapper
    return func(self, *args, **kwargs)
           ^^^^^^^^^^^^^^^^^^^^^^^^^^^
  File "/home/airflow/.local/lib/python3.12/site-packages/airflow/operators/python.py", line 437, in execute
    return super().execute(context=serializable_context)
           ^^^^^^^^^^^^^^^^^^^^^^^^^^^^^^^^^^^^^^^^^^^^^
  File "/home/airflow/.local/lib/python3.12/site-packages/airflow/models/baseoperator.py", line 401, in wrapper
    return func(self, *args, **kwargs)
           ^^^^^^^^^^^^^^^^^^^^^^^^^^^
  File "/home/airflow/.local/lib/python3.12/site-packages/airflow/operators/python.py", line 235, in execute
    return_value = self.execute_callable()
                   ^^^^^^^^^^^^^^^^^^^^^^^
  File "/home/airflow/.local/lib/python3.12/site-packages/airflow/operators/python.py", line 759, in execute_callable
    result = self._execute_python_callable_in_subprocess(python_path)
             ^^^^^^^^^^^^^^^^^^^^^^^^^^^^^^^^^^^^^^^^^^^^^^^^^^^^^^^^
  File "/home/airflow/.local/lib/python3.12/site-packages/airflow/operators/python.py", line 514, in _execute_python_callable_in_subprocess
    raise AirflowException(error_msg) from None
airflow.exceptions.AirflowException: Process returned non-zero exit status 1.
[Errno 2] No such file or directory: '/opt/***/dags/data/model/best_lasso_model.joblib'
[2024-10-12T04:29:29.790-0500] {taskinstance.py:1206} INFO - Marking task as FAILED. dag_id=monitor_maintain_dag_v1_3, task_id=prediction_model, run_id=manual__2024-10-12T09:24:17.715612+00:00, execution_date=20241012T092417, start_date=20241012T092849, end_date=20241012T092929
[2024-10-12T04:29:29.804-0500] {standard_task_runner.py:110} ERROR - Failed to execute job 41 for task prediction_model (Process returned non-zero exit status 1.
[Errno 2] No such file or directory: '/opt/***/dags/data/model/best_lasso_model.joblib'; 263)
[2024-10-12T04:29:29.813-0500] {local_task_job_runner.py:243} INFO - Task exited with return code 1
[2024-10-12T04:29:29.836-0500] {taskinstance.py:3503} INFO - 0 downstream tasks scheduled from follow-on schedule check
[2024-10-12T04:29:29.841-0500] {local_task_job_runner.py:222} INFO - ::endgroup::
